2023-04-13 21:15:38,069 ERROR: Exception on /create_event [GET] [in /Users/smirsepahi/Documents/Code/microblog/venv/lib/python3.11/site-packages/flask/app.py:1741]
Traceback (most recent call last):
  File "/Users/smirsepahi/Documents/Code/microblog/venv/lib/python3.11/site-packages/flask/app.py", line 2525, in wsgi_app
    response = self.full_dispatch_request()
               ^^^^^^^^^^^^^^^^^^^^^^^^^^^^
  File "/Users/smirsepahi/Documents/Code/microblog/venv/lib/python3.11/site-packages/flask/app.py", line 1822, in full_dispatch_request
    rv = self.handle_user_exception(e)
         ^^^^^^^^^^^^^^^^^^^^^^^^^^^^^
  File "/Users/smirsepahi/Documents/Code/microblog/venv/lib/python3.11/site-packages/flask/app.py", line 1820, in full_dispatch_request
    rv = self.dispatch_request()
         ^^^^^^^^^^^^^^^^^^^^^^^
  File "/Users/smirsepahi/Documents/Code/microblog/venv/lib/python3.11/site-packages/flask/app.py", line 1796, in dispatch_request
    return self.ensure_sync(self.view_functions[rule.endpoint])(**view_args)
           ^^^^^^^^^^^^^^^^^^^^^^^^^^^^^^^^^^^^^^^^^^^^^^^^^^^^^^^^^^^^^^^^^
  File "/Users/smirsepahi/Documents/Code/EventIt/app/routes.py", line 51, in create_event
    return render_template('create_event.html', title='Create Event', form=form, posts=posts.items)
                                                                                       ^^^^^
NameError: name 'posts' is not defined
2023-04-13 21:16:10,281 INFO: Microblog startup [in /Users/smirsepahi/Documents/Code/EventIt/app/__init__.py:45]
2023-04-13 21:16:21,730 ERROR: Exception on /create_event [POST] [in /Users/smirsepahi/Documents/Code/microblog/venv/lib/python3.11/site-packages/flask/app.py:1741]
Traceback (most recent call last):
  File "/Users/smirsepahi/Documents/Code/microblog/venv/lib/python3.11/site-packages/sqlalchemy/sql/base.py", line 2120, in _entity_namespace_key
    return getattr(ns, key)  # type: ignore
           ^^^^^^^^^^^^^^^^
AttributeError: type object 'User' has no attribute 'eventName'

The above exception was the direct cause of the following exception:

Traceback (most recent call last):
  File "/Users/smirsepahi/Documents/Code/microblog/venv/lib/python3.11/site-packages/flask/app.py", line 2525, in wsgi_app
    response = self.full_dispatch_request()
               ^^^^^^^^^^^^^^^^^^^^^^^^^^^^
  File "/Users/smirsepahi/Documents/Code/microblog/venv/lib/python3.11/site-packages/flask/app.py", line 1822, in full_dispatch_request
    rv = self.handle_user_exception(e)
         ^^^^^^^^^^^^^^^^^^^^^^^^^^^^^
  File "/Users/smirsepahi/Documents/Code/microblog/venv/lib/python3.11/site-packages/flask/app.py", line 1820, in full_dispatch_request
    rv = self.dispatch_request()
         ^^^^^^^^^^^^^^^^^^^^^^^
  File "/Users/smirsepahi/Documents/Code/microblog/venv/lib/python3.11/site-packages/flask/app.py", line 1796, in dispatch_request
    return self.ensure_sync(self.view_functions[rule.endpoint])(**view_args)
           ^^^^^^^^^^^^^^^^^^^^^^^^^^^^^^^^^^^^^^^^^^^^^^^^^^^^^^^^^^^^^^^^^
  File "/Users/smirsepahi/Documents/Code/EventIt/app/routes.py", line 44, in create_event
    event_name = User.query.filter_by(eventName=form.eventName.data, eventDate=form.eventDate.data)
                 ^^^^^^^^^^^^^^^^^^^^^^^^^^^^^^^^^^^^^^^^^^^^^^^^^^^^^^^^^^^^^^^^^^^^^^^^^^^^^^^^^^
  File "/Users/smirsepahi/Documents/Code/microblog/venv/lib/python3.11/site-packages/sqlalchemy/orm/query.py", line 1998, in filter_by
    clauses = [
              ^
  File "/Users/smirsepahi/Documents/Code/microblog/venv/lib/python3.11/site-packages/sqlalchemy/orm/query.py", line 1999, in <listcomp>
    _entity_namespace_key(from_entity, key) == value
    ^^^^^^^^^^^^^^^^^^^^^^^^^^^^^^^^^^^^^^^
  File "/Users/smirsepahi/Documents/Code/microblog/venv/lib/python3.11/site-packages/sqlalchemy/sql/base.py", line 2122, in _entity_namespace_key
    raise exc.InvalidRequestError(
sqlalchemy.exc.InvalidRequestError: Entity namespace for "user" has no property "eventName"
2023-04-13 21:20:16,446 INFO: Microblog startup [in /Users/smirsepahi/Documents/Code/EventIt/app/__init__.py:45]
2023-04-13 21:20:26,814 ERROR: Exception on /create_event [POST] [in /Users/smirsepahi/Documents/Code/microblog/venv/lib/python3.11/site-packages/flask/app.py:1741]
Traceback (most recent call last):
  File "/Users/smirsepahi/Documents/Code/microblog/venv/lib/python3.11/site-packages/sqlalchemy/sql/base.py", line 2120, in _entity_namespace_key
    return getattr(ns, key)  # type: ignore
           ^^^^^^^^^^^^^^^^
AttributeError: type object 'User' has no attribute 'eventName'

The above exception was the direct cause of the following exception:

Traceback (most recent call last):
  File "/Users/smirsepahi/Documents/Code/microblog/venv/lib/python3.11/site-packages/flask/app.py", line 2525, in wsgi_app
    response = self.full_dispatch_request()
               ^^^^^^^^^^^^^^^^^^^^^^^^^^^^
  File "/Users/smirsepahi/Documents/Code/microblog/venv/lib/python3.11/site-packages/flask/app.py", line 1822, in full_dispatch_request
    rv = self.handle_user_exception(e)
         ^^^^^^^^^^^^^^^^^^^^^^^^^^^^^
  File "/Users/smirsepahi/Documents/Code/microblog/venv/lib/python3.11/site-packages/flask/app.py", line 1820, in full_dispatch_request
    rv = self.dispatch_request()
         ^^^^^^^^^^^^^^^^^^^^^^^
  File "/Users/smirsepahi/Documents/Code/microblog/venv/lib/python3.11/site-packages/flask/app.py", line 1796, in dispatch_request
    return self.ensure_sync(self.view_functions[rule.endpoint])(**view_args)
           ^^^^^^^^^^^^^^^^^^^^^^^^^^^^^^^^^^^^^^^^^^^^^^^^^^^^^^^^^^^^^^^^^
  File "/Users/smirsepahi/Documents/Code/EventIt/app/routes.py", line 44, in create_event
    event_name = User.query.filter_by(eventName=form.eventName.data, eventDate=form.eventDate.data)
                 ^^^^^^^^^^^^^^^^^^^^^^^^^^^^^^^^^^^^^^^^^^^^^^^^^^^^^^^^^^^^^^^^^^^^^^^^^^^^^^^^^^
  File "/Users/smirsepahi/Documents/Code/microblog/venv/lib/python3.11/site-packages/sqlalchemy/orm/query.py", line 1998, in filter_by
    clauses = [
              ^
  File "/Users/smirsepahi/Documents/Code/microblog/venv/lib/python3.11/site-packages/sqlalchemy/orm/query.py", line 1999, in <listcomp>
    _entity_namespace_key(from_entity, key) == value
    ^^^^^^^^^^^^^^^^^^^^^^^^^^^^^^^^^^^^^^^
  File "/Users/smirsepahi/Documents/Code/microblog/venv/lib/python3.11/site-packages/sqlalchemy/sql/base.py", line 2122, in _entity_namespace_key
    raise exc.InvalidRequestError(
sqlalchemy.exc.InvalidRequestError: Entity namespace for "user" has no property "eventName"
2023-04-13 21:21:47,380 INFO: Microblog startup [in /Users/smirsepahi/Documents/Code/EventIt/app/__init__.py:45]
2023-04-13 21:28:28,658 INFO: Microblog startup [in /Users/smirsepahi/Documents/Code/EventIt/app/__init__.py:45]
2023-04-13 21:29:37,855 INFO: Microblog startup [in /Users/smirsepahi/Documents/Code/EventIt/app/__init__.py:45]
2023-04-13 21:29:49,425 ERROR: Exception on /create_event [POST] [in /Users/smirsepahi/Documents/Code/microblog/venv/lib/python3.11/site-packages/flask/app.py:1741]
Traceback (most recent call last):
  File "/Users/smirsepahi/Documents/Code/microblog/venv/lib/python3.11/site-packages/flask/app.py", line 2525, in wsgi_app
    response = self.full_dispatch_request()
               ^^^^^^^^^^^^^^^^^^^^^^^^^^^^
  File "/Users/smirsepahi/Documents/Code/microblog/venv/lib/python3.11/site-packages/flask/app.py", line 1822, in full_dispatch_request
    rv = self.handle_user_exception(e)
         ^^^^^^^^^^^^^^^^^^^^^^^^^^^^^
  File "/Users/smirsepahi/Documents/Code/microblog/venv/lib/python3.11/site-packages/flask/app.py", line 1820, in full_dispatch_request
    rv = self.dispatch_request()
         ^^^^^^^^^^^^^^^^^^^^^^^
  File "/Users/smirsepahi/Documents/Code/microblog/venv/lib/python3.11/site-packages/flask/app.py", line 1796, in dispatch_request
    return self.ensure_sync(self.view_functions[rule.endpoint])(**view_args)
           ^^^^^^^^^^^^^^^^^^^^^^^^^^^^^^^^^^^^^^^^^^^^^^^^^^^^^^^^^^^^^^^^^
  File "/Users/smirsepahi/Documents/Code/EventIt/app/routes.py", line 44, in create_event
    post = Post(body=form.eventName.data + form.eventDate.data, author=current_user)
                     ~~~~~~~~~~~~~~~~~~~~^~~~~~~~~~~~~~~~~~~~~
TypeError: can only concatenate str (not "datetime.date") to str
2023-04-13 21:30:08,653 INFO: Microblog startup [in /Users/smirsepahi/Documents/Code/EventIt/app/__init__.py:45]
2023-04-13 21:30:54,243 INFO: Microblog startup [in /Users/smirsepahi/Documents/Code/EventIt/app/__init__.py:45]
